<?xml version="1.0" encoding="utf-8"?>
<robot name="ranger_mini_complete" xmlns:xacro="http://ros.org/wiki/xacro">

  <xacro:property name="M_PI" value="3.14159265359"/>
  <xacro:property name="base_to_footprint_z" value="0.33"/>
  <xacro:property name="lidar_x" value="0.33"/>
  <xacro:property name="lidar_y" value="0.0"/>
  <xacro:property name="lidar_z" value="0.0"/>
  <xacro:property name="camera_x" value="0.28"/>
  <xacro:property name="camera_y" value="0.0"/>
  <xacro:property name="camera_z" value="0.115"/>
  <xacro:property name="arm_x" value="0.0"/>
  <xacro:property name="arm_y" value="0.0"/>
  <xacro:property name="arm_z" value="0.30"/>

  <link
    name="base_link">
    <inertial>
      <origin
        xyz="-0.0242698272228022 -0.0030308024613212 0.0544267444673498"
        rpy="0 0 0" />
      <mass
        value="10" />
      <inertia ixx="0.1354" ixy="0.0" ixz="0.0" iyy="0.2417" iyz="0.0" izz="0.3085"/>
    </inertial>
    <visual>
      <origin
        xyz="0 0 0.0"
        rpy="0 0 0" />
      <geometry>
        <mesh
          filename="package://ranger_description/meshes/ranger_base.dae" scale="1000 1000 1000" />
      </geometry>
      <material
        name="">
        <color
          rgba="0.792156862745098 0.819607843137255 0.933333333333333 1" />
      </material>
    </visual>
        <collision>
            <origin xyz="0 0 -0.1" rpy="0 0 0" />
            <geometry>
                <box size="0.5 0.35 0.2"/>
            </geometry>
        </collision>
   </link>

  <link name="base_footprint"/>

  <joint name="base_footprint_joint" type="fixed">
    <parent link="base_footprint"/>
    <child link="base_link"/>
    <origin xyz="0 0 ${base_to_footprint_z}" rpy="0 0 0"/>
  </joint>

   <link
    name="fr_steering_wheel_link">
    <inertial>
      <origin
        xyz="1.8493E-05 1.2713E-06 0.043679"
        rpy="0 0 0" />
      <mass
        value="1" />
      <inertia
        ixx="0.0063625"
        ixy="-1.0581E-07"
        ixz="-4.0831E-07"
        iyy="0.006363"
        iyz="-3.4944E-08"
        izz="0.010465" />
    </inertial>
    <visual>
      <origin
        xyz="0 0 0"
        rpy="0 0 0" />
      <geometry>
        <mesh filename="package://ranger_description/meshes/steering_wheel.dae" scale="10 10 10"/>
      </geometry>
      <material
        name="">
        <color
          rgba="0.79216 0.81961 0.93333 1" />
      </material>
    </visual>
    <collision>
      <origin
        xyz="0 0 0"
        rpy="0 0 0" />
      <geometry>
          <cylinder radius="0.001" length="0.001"/>
      </geometry>
    </collision>
  </link>
  <joint
    name="fr_steering_joint"
    type="revolute">     
    <origin
      xyz="0.25 -0.19 -0.1"
      rpy="0 0 0" />
    <parent
      link="base_link" />
    <child
      link="fr_steering_wheel_link" />
    <axis
      xyz="0 0 -1" />
    <limit effort="5" velocity="6.28"  lower="-2.1" upper="2.1" />

  </joint>


  <link name="fr_wheel_link">
      <inertial>
          <mass value="8" />
          <origin xyz="0 0 0" />
          <inertia ixx="0.02047" ixy="0.0" ixz="0.0" iyy="0.02047" iyz="0.0" izz="0.0324"/>            
          </inertial>
      <visual>
          <origin xyz="0 0 0" rpy="3.14 0 0" />
          <geometry>
            <mesh filename="package://ranger_description/meshes/wheel_v3.dae" scale="10 10 10"/>
          </geometry>
      </visual>
      <collision>
          <origin xyz="0 0 -0.005" rpy="1.57 0 0" />
          <geometry>
              <cylinder length="0.08" radius="0.09" />
          </geometry>
                <contact>
                    <ode>
                  <min_depth>0.001</min_depth>
                    </ode>
              </contact>
      </collision>
  </link>

        <joint name="fr_wheel" type="continuous">
            <origin xyz="0.0 0.0 -0.12" rpy="0 0 0" />
            <parent link="fr_steering_wheel_link"/>
            <child link="fr_wheel_link"/>
            <axis xyz="0 1 0" rpy="0 0 0" />
        </joint>


  <link
    name="fl_steering_wheel_link">
    <inertial>
      <origin
        xyz="-0.0017956 -9.6304E-08 0.043642"
        rpy="0 0 0" />
      <mass
        value="1" />
      <inertia
        ixx="0.0063695"
        ixy="-2.1067E-08"
        ixz="-0.00016867"
        iyy="0.006363"
        iyz="-1.0301E-08"
        izz="0.010458" />
    </inertial>
    <visual>
      <origin
        xyz="0 0 0"
        rpy="0 0 3.14" />
      <geometry>
        <mesh filename="package://ranger_description/meshes/steering_wheel.dae" scale="10 10 10"/>
      </geometry>
      <material
        name="">
        <color
          rgba="0.79216 0.81961 0.93333 1" />
      </material>
    </visual>
    <collision>
      <origin
        xyz="0 0 0"
        rpy="0 0 0" />
      <geometry>
        <cylinder radius="0.001" length="0.001"/>
      </geometry>
    </collision>
  </link>
   <joint
    name="fl_steering_joint"
    type="revolute">
    <origin
      xyz="0.25 0.19 -0.1"     
      rpy="0 0 0" />
    <parent
      link="base_link" />
    <child
      link="fl_steering_wheel_link" />
    <axis
      xyz="0 0 -1" />
        <limit effort="5" velocity="6.28"  lower="-2.1" upper="2.1" />

  </joint>

        <link name="fl_wheel_link">
            <inertial>
                <mass value="8" />
                <origin xyz="0 0 0" />
                <inertia ixx="0.02047" ixy="0.0" ixz="0.0" iyy="0.02047" iyz="0.0" izz="0.0324"/>            
            </inertial>
            <visual>
                <origin xyz="0 0 0" rpy="0 0 0" />
                <geometry>
                <mesh filename="package://ranger_description/meshes/wheel_v3.dae" scale="10 10 10"/>
                </geometry>
            </visual>
            <collision>
                <origin xyz="0 0 -0.005" rpy="1.57 0 0" />
                <geometry>
                    <cylinder length="0.08" radius="0.09" />
                </geometry>
                     <contact>
                         <ode>
                        <min_depth>0.001</min_depth>
                         </ode>
                    </contact>
            </collision>
        </link>

        <joint name="fl_wheel" type="continuous">
            <origin xyz="0.0 0.0 -0.12" rpy="0 0 0" />
            <parent link="fl_steering_wheel_link"/>
            <child link="fl_wheel_link"/>
            <axis xyz="0 1 0" rpy="0 0 0" />
        </joint>

 <link
    name="rl_steering_wheel_link">
    <inertial>
      <origin
        xyz="-0.00017093 6.1255E-08 0.043678"
        rpy="0 0 0" />
      <mass
        value="1" />
      <inertia
        ixx="0.0063627"
        ixy="-2.1069E-08"
        ixz="-1.587E-05"
        iyy="0.006363"
        iyz="9.3201E-09"
        izz="0.010465" />
    </inertial>
    <visual>
      <origin
        xyz="0 0 0"
        rpy="0 0 3.14" />
      <geometry>
        <mesh filename="package://ranger_description/meshes/steering_wheel.dae" scale="10 10 10"/>
      </geometry>
      <material
        name="">
        <color
          rgba="0.79216 0.81961 0.93333 1" />
      </material>
    </visual>
    <collision>
      <origin
        xyz="0 0 0"
        rpy="0 0 0" />
      <geometry>
        <cylinder radius="0.001" length="0.001"/>
      </geometry>
    </collision>
  </link>

  <joint
    name="rl_steering_joint"
    type="revolute">
    <origin
      xyz="-0.25 0.19 -0.1"
      rpy="0 0 0" />
    <parent
      link="base_link" />
    <child
      link="rl_steering_wheel_link" />
    <axis
      xyz="0 0 -1" />
        <limit effort="5" velocity="6.28"  lower="-2.1" upper="2.1" />
  </joint>

        <link name="rl_wheel_link">
            <inertial>
                <mass value="8" />
                <origin xyz="0 0 0" />
                <inertia ixx="0.02047" ixy="0.0" ixz="0.0" iyy="0.02047" iyz="0.0" izz="0.0324"/>            
            </inertial>
            <visual>
                <origin xyz="0 0 0" rpy="0 0 0" />
                <geometry>
                  <mesh filename="package://ranger_description/meshes/wheel_v3.dae" scale="10 10 10"/>
                </geometry>
            </visual>
            <collision>
                <origin xyz="0.00 0.00 -0.005" rpy="1.57 0 0" />
                <geometry>
                    <cylinder length="0.08" radius="0.09" />
                </geometry>
                     <contact>
                         <ode>
                        <min_depth>0.001</min_depth>
                         </ode>
                    </contact>
            </collision>
        </link>

        <joint name="rl_wheel" type="continuous">
            <origin xyz="0.0 0.0 -0.12 " rpy="0 0 0" />
            <parent link="rl_steering_wheel_link"/>
            <child link="rl_wheel_link"/>
            <axis xyz="0 1 0" rpy="0 0 0" />
        </joint>

   <link name="rr_steering_wheel_link">
        <inertial>
            <origin xyz="0.0 0.0 0.0"/>
            <mass value="1"/>
            <inertia ixx="0.01" ixy="0.0" ixz="0.0" iyy="0.01" iyz="0.0" izz="0.01"/>
        </inertial>
        <visual>
          <origin
            xyz="0 0 0"
            rpy="0 0 0" />
          <geometry>
            <mesh filename="package://ranger_description/meshes/steering_wheel.dae" scale="10 10 10"/>
          </geometry>
        </visual>
        <collision>
            <origin  xyz="0 0 0" rpy="0 0 0" />
                    <geometry>
                <cylinder radius="0.001" length="0.001"/>
            </geometry>
        </collision>
    </link>
    <joint name="rr_steering_joint" type="revolute">
        <origin xyz="-0.23 -0.206 -0.1" rpy="0 0 0" />
        <parent link="base_link"/>
        <child link="rr_steering_wheel_link"/>
        <axis xyz="0 0 -1" rpy="0 0 0" />
        <limit effort="5" velocity="6.28"  lower="-2.1" upper="2.1" />
    </joint>

       <link name="rr_wheel_link">
            <inertial>
                <mass value="8" />
                <origin xyz="0 0 0" />
                <inertia ixx="0.02047" ixy="0.0" ixz="0.0" iyy="0.02047" iyz="0.0" izz="0.0324"/>            
            </inertial>
            <visual>
                <origin xyz="0.0 0.0 0.0" rpy="3.14 0 0" />
                <geometry>
                    <mesh filename="package://ranger_description/meshes/wheel_v3.dae" scale="10 10 10"/>
                </geometry>
            </visual>
            <collision>
                <origin xyz="0.0 0.0 -0.005" rpy="1.57 0 0" />
                <geometry>
                    <cylinder length="0.08" radius="0.09" />
                </geometry>
                     <contact>
                         <ode>
                        <min_depth>0.001</min_depth>
                         </ode>
                    </contact>
            </collision>
        </link>

        <joint name="rr_wheel" type="continuous">
            <origin xyz="0.0 0.0 -0.12 " rpy="0 0 0" />
            <parent link="rr_steering_wheel_link"/>
            <child link="rr_wheel_link"/>
            <axis xyz="0 1 0" rpy="0 0 0" />
        </joint>

<!-- 
	<transmission name="fl_steering_wheel_trans">
      <type>transmission_interface/SimpleTransmission</type>
      <joint name="fl_steering_joint">
		<hardwareInterface>hardware_interface/PositionJointInterface</hardwareInterface>
      </joint>
	  <actuator name="fl_steering_wheel_motor">
		<hardwareInterface>hardware_interface/PositionJointInterface</hardwareInterface>
		<mechanicalReduction>30</mechanicalReduction>
      </actuator>
	</transmission>

	<transmission name="fr_steering_wheel_trans">
      <type>transmission_interface/SimpleTransmission</type>
      <joint name="fr_steering_joint">
		<hardwareInterface>hardware_interface/PositionJointInterface</hardwareInterface>
      </joint>
	  <actuator name="fr_steering_wheel_motor">
		<hardwareInterface>hardware_interface/PositionJointInterface</hardwareInterface>
		<mechanicalReduction>30</mechanicalReduction>
      </actuator>
	</transmission>

	<transmission name="rl_steering_wheel_trans">
      <type>transmission_interface/SimpleTransmission</type>
      <joint name="rl_steering_joint">
		<hardwareInterface>hardware_interface/PositionJointInterface</hardwareInterface>
      </joint>
	  <actuator name="rl_steering_wheel_motor">
		<hardwareInterface>hardware_interface/PositionJointInterface</hardwareInterface>
		<mechanicalReduction>30</mechanicalReduction>
      </actuator>
	</transmission>

	<transmission name="rr_steering_wheel_trans">
      <type>transmission_interface/SimpleTransmission</type>
      <joint name="rr_steering_joint">
		<hardwareInterface>hardware_interface/PositionJointInterface</hardwareInterface>
      </joint>
	  <actuator name="rr_steering_wheel_motor">
		<hardwareInterface>hardware_interface/PositionJointInterface</hardwareInterface>
		<mechanicalReduction>30</mechanicalReduction>
      </actuator>
	</transmission>

	<transmission name="fl_wheel_trans">
      <type>transmission_interface/SimpleTransmission</type>
      <joint name="fl_wheel">
		<hardwareInterface>hardware_interface/VelocityJointInterface</hardwareInterface>
      </joint>
	  <actuator name="fl_wheel_motor">
		<hardwareInterface>hardware_interface/VelocityJointInterface</hardwareInterface>
		<mechanicalReduction>30</mechanicalReduction>
      </actuator>
	</transmission>

	<transmission name="fr_wheel_trans">
      <type>transmission_interface/SimpleTransmission</type>
      <joint name="fr_wheel">
		<hardwareInterface>hardware_interface/VelocityJointInterface</hardwareInterface>
      </joint>
	  <actuator name="fr_wheel_motor">
		<hardwareInterface>hardware_interface/VelocityJointInterface</hardwareInterface>
		<mechanicalReduction>30</mechanicalReduction>
      </actuator>
	</transmission>

	<transmission name="rl_wheel_trans">
      <type>transmission_interface/SimpleTransmission</type>
      <joint name="rl_wheel">
		<hardwareInterface>hardware_interface/VelocityJointInterface</hardwareInterface>
      </joint>
	  <actuator name="rl_wheel_motor">
		<hardwareInterface>hardware_interface/VelocityJointInterface</hardwareInterface>
		<mechanicalReduction>30</mechanicalReduction>
      </actuator>
	</transmission>

	<transmission name="rr_wheel_trans">
      <type>transmission_interface/SimpleTransmission</type>
      <joint name="rr_wheel">
		<hardwareInterface>hardware_interface/VelocityJointInterface</hardwareInterface>
      </joint>
	  <actuator name="rr_wheel_motor">
		<hardwareInterface>hardware_interface/VelocityJointInterface</hardwareInterface>
		<mechanicalReduction>30</mechanicalReduction>
      </actuator>
	</transmission>
  <gazebo>
    <plugin name="gazebo_ros_control" filename="libgazebo_ros_control.so">
    </plugin>
  </gazebo> -->

  <!-- LiDAR Link (Livox Mid-360) -->
  <link name="lidar_link">
    <visual>
      <geometry>
        <cylinder radius="0.05" length="0.08"/>
      </geometry>
      <material name="black">
        <color rgba="0.1 0.1 0.1 1.0"/>
      </material>
    </visual>
    <collision>
      <geometry>
        <cylinder radius="0.05" length="0.08"/>
      </geometry>
    </collision>
    <inertial>
      <mass value="0.3"/>
      <origin xyz="0 0 0"/>
      <inertia ixx="0.001" ixy="0.0" ixz="0.0"
               iyy="0.001" iyz="0.0"
               izz="0.001"/>
    </inertial>
  </link>

  <joint name="lidar_mount" type="fixed">
    <parent link="base_link"/>
    <child link="lidar_link"/>
    <origin xyz="${lidar_x} ${lidar_y} ${lidar_z}" rpy="0 ${pi/4} 0"/>
  </joint>

  <!-- Camera Link (RealSense D435) -->
  <link name="camera_link">
    <visual>
      <geometry>
        <box size="0.025 0.090 0.025"/>
      </geometry>
      <material name="silver">
        <color rgba="0.8 0.8 0.8 1.0"/>
      </material>
    </visual>
    <collision>
      <geometry>
        <box size="0.090 0.025 0.025"/>
      </geometry>
    </collision>
    <inertial>
      <mass value="0.072"/>
      <origin xyz="0 0 0"/>
      <inertia ixx="0.0001" ixy="0.0" ixz="0.0"
               iyy="0.0001" iyz="0.0"
               izz="0.0001"/>
    </inertial>
  </link>

  <joint name="camera_mount" type="fixed">
    <parent link="base_link"/>
    <child link="camera_link"/>
    <origin xyz="${camera_x} ${camera_y} ${camera_z}" rpy="0 0 0"/>
  </joint>

  <!-- Camera depth optical frame -->
  <link name="camera_depth_optical_frame"/>

  <joint name="camera_depth_optical_joint" type="fixed">
    <parent link="camera_link"/>
    <child link="camera_depth_optical_frame"/>
    <origin xyz="0 0 0" rpy="${-M_PI/2} 0 ${-M_PI/2}"/>
  </joint>

  <!-- Camera color optical frame -->
  <link name="camera_color_optical_frame"/>

  <joint name="camera_color_optical_joint" type="fixed">
    <parent link="camera_link"/>
    <child link="camera_color_optical_frame"/>
    <origin xyz="0 0 0" rpy="${-M_PI/2} 0 ${-M_PI/2}"/>
  </joint>

  <!-- PiPER Arm Base Link (placeholder - actual arm from piper_ros) -->
  <link name="piper_base_link">
    <visual>
      <geometry>
        <cylinder radius="0.06" length="0.10"/>
      </geometry>
      <material name="blue">
        <color rgba="0.2 0.2 0.8 1.0"/>
      </material>
    </visual>
    <collision>
      <geometry>
        <cylinder radius="0.06" length="0.10"/>
      </geometry>
    </collision>
    <inertial>
      <mass value="1.0"/>
      <origin xyz="0 0 0"/>
      <inertia ixx="0.01" ixy="0.0" ixz="0.0"
               iyy="0.01" iyz="0.0"
               izz="0.01"/>
    </inertial>
  </link>

  <joint name="arm_mount" type="fixed">
    <parent link="base_link"/>
    <child link="piper_base_link"/>
    <origin xyz="${arm_x} ${arm_y} ${arm_z}" rpy="0 0 0"/>
  </joint>

</robot>
